Workbook

Sheet datasets
A1: Code | B1: Name | C1: Description | D1: Reference | E1: Year | F1: URL | G1: License | H1: Artifact type | I1: Granularity | J1: RE stage | K1: Task | L1: Domain | M1: Size | N1: Languages | O1: Labels | P1: Extends | Q1: Publications
A2: D001 | B2: Acharya2024 | C2: Bugzilla bug reports gathered from June 2015 through December 2023, annotated with priority and severity labels. | D2: Acharya, J., & Ginde, G. (2024). Graph Neural Network vs. Large Language Model: A Comparative Analysis for Bug Report Priority and Severity Prediction [Data set]. Zenodo. https://doi.org/10.5281/zenodo.10892319 | E2: 2024 | F2: https://zenodo.org/records/10892319 | G2: Creative Commons Attribution Share Alike 4.0 International | H2: Bug | I2: Document | J2: verification & validation | K2: classification | L2: software | M2: 452257 | N2: en | O2: P1,P2,P3,P4,P5;Normal,S3,S4,Critical | P2: - | Q2: P074
A3: D002 | B3: AeroReqEval | C3: QA pairs across tasks and formulas for understanding of aerospace software requirements. | D3: Yang, L., Luo, Y., Gao, H., Fan, Y., Zhang, J., Li, X., Dong, X., Gu, B., Jin, Z., & Yang, M. (2025). Evaluating large language models for requirements question answering in industrial aerospace software. In Proceedings of the 33rd ACM International Conference on the Foundations of Software Engineering (FSE Companion ’25) (pp. 366–377). Association for Computing Machinery. https://doi.org/10.1145/3696630.3728560 | E3: 2025 | F3: https://anonymous.4open.science/r/AeroReqEval-19BD | G3: None | H3: QA | I3: Pair | J3: analysis | K3: Q&A | L3: aerospace | M3: 6696 | N3: en | O3: - | P3: - | Q3: P009
A4: D003 | B4: AutoFactory | C4: Manufacturing requirements labelled with BIO tags to extract key components and support PLC code generation | D4: Boudribila, A., Tajer, A., & Boulghasoul, Z. (2025). AutoFactory dataset to support AI in manufacturing systems. Data in Brief, 62, 111938. https://doi.org/10.1016/j.dib.2025.111938 | E4: 2025 | F4: https://huggingface.co/datasets/boudribila/AutoFactory | G4: None | H4: Requirements | I4: Token | J4: specification | K4: classification | L4: manufacturing | M4: 279830 | N4: en | O4: Actuator,Pre-actuator,Sensor,Defector,Other | P4: - | Q4: P026
A5: D004 | B5: AWARE | C5: App reviews annotated with aspect terms, categories, and sentiments | D5: Nouf Alturaief, Hamoud Aljamaan, & Malak Baslyman. (2021). AWARE: Dataset for Aspect-Based Sentiment Analysis of Apps Reviews (1.0.0) [Data set]. 36th IEEE/ACM International Conference on Automated Software Engineering Workshops (ASEW). Zenodo. https://doi.org/10.5281/zenodo.5528481 | E5: 2021 | F5: https://zenodo.org/records/5528481 | G5: Creative Commons Attribution 4.0 International | H5: User reviews | I5: Sentence | J5: verification & validation | K5: classification | L5: mobile | M5: 11482 | N5: en | O5: - | P5: - | Q5: P093
A6: D005 | B6: Azeem2023 | C6: Data processing agreements (DPAs) sentences annotated with GDPR provisions (P1...P19) | D6: Azeem, M.I., Abualhaija, S. A Multi-solution Study on GDPR AI-enabled Completeness Checking of DPAs. Empir Software Eng 29, 96 (2024). https://doi.org/10.1007/s10664-024-10491-3 | E6: 2023 | F6: https://figshare.com/s/77338e558ffb6adf6f55 | G6: Creative Commons Attribution Share Alike 4.0 International | H6: Legal text | I6: Sentence | J6: verification & validation | K6: classification | L6: legal | M6: 31185 | N6: en | O6: Provision 1, Provision 2, Provision 3, Provision 4, Provision 5, Provision 6, Provision 7, Provision 8, Provision 9, Provision 10, Provision 11, Provision 12, Provision 13, Provision 14, Provision 15, Provision 16, Provision 17, Provision 18, Provision 19 | P6: - | Q6: P075
A7: D006 | B7: Bozygit2024 | C7: Functional requirements from various software systems, such as educational, business, and hospitality settings. | D7: Fatma Bozyigit, Tolgahan Bardakci, Alireza Khalilipour, Moharram Challenger, Guus Ramackers, Onder Babur, Michel R. V. Chaudron (2023). Dataset for: Text Requirements to Models. IEEE Dataport. https://dx.doi.org/10.21227/r9j6-nd62 | E7: 2023 | F7: https://ieee-dataport.org/documents/dataset-text-requirements-models | G7: None | H7: Requirements | I7: Document | J7: analysis | K7: extraction | L7: education,business,healthcare | M7: 120 | N7: en | O7: - | P7: D046 | Q7: P065
A8: D007 | B8: Bragilovski2024 | C8: User stories dataset from three collections from online repositories classified according to project-specific knowledge. | D8: Bragilovski, M., van Can, A. T., Dalpiaz, F., & Sturm, A. (2024). Material of the paper "Deriving Domain Models from User Stories: Human vs. Machines" [Data set]. Zenodo. https://doi.org/10.5281/zenodo.12740518 | E8: 2024 | F8: https://zenodo.org/records/12740518 | G8: Creative Commons Attribution Share Alike 4.0 International | H8: User stories | I8: Document | J8: specification | K8: modelling | L8: services,software,education | M8: 487 | N8: en | O8: - | P8: - | Q8: P013,P112
A9: D008 | B9: Bugzilla_conflicts | C9: Post pairs from Bugzilla labeled as "conflict" or "neutral". | D9: Malik, G., Cevik, M., & Başar, A. (2023). Data augmentation for conflict and duplicate detection in software engineering sentence pairs. In Proceedings of the 33rd Annual International Conference on Computer Science and Software Engineering (CASCON ’23) (pp. 34–43). | E9: 2023 | F9: https://gitfront.io/r/user-9946871/ii6eJFSh7oT4/DA-Sentence-Pairs/ | G9: None | H9: Post | I9: Pair | J9: management | K9: traceability | L9: software | M9: 4090 | N9: en | O9: Neutral,Conflict | P9: - | Q9: P005
A10: D009 | B10: CCHIT | C10: Cross-level requirements dataset for traceability tasks from the Certification Commission for Healthcare Information Technology healthcare project | D10: C. Ge, T. Wang, X. Yang and C. Treude, "Cross-Level Requirements Tracing Based on Large Language Models," in IEEE Transactions on Software Engineering, vol. 51, no. 7, pp. 2044-2066, July 2025, doi: 10.1109/TSE.2025.3572094. | E10: 2025 | F10: https://github.com/Gechuyan/Cross-Level-Requirements-Tracing-Based-on-Large-Language-Model/blob/main/Cross-Level%20Requirements%20Tracing%20Based%20on%20Large%20Language%20Model/Data/Original_Data/CCHIT.csv | G10: None | H10: Requirements | I10: Pair | J10: management | K10: traceability | L10: healthcare | M10: 252 | N10: en | O10: Positive,Negative | P10: - | Q10: P049,P058,P116
A11: D010 | B11: CM1 | C11: Cross-level requirements dataset for traceability tasks from the CM1 aerospace project | D11: C. Ge, T. Wang, X. Yang and C. Treude, "Cross-Level Requirements Tracing Based on Large Language Models," in IEEE Transactions on Software Engineering, vol. 51, no. 7, pp. 2044-2066, July 2025, doi: 10.1109/TSE.2025.3572094. | E11: 2025 | F11: https://github.com/Gechuyan/Cross-Level-Requirements-Tracing-Based-on-Large-Language-Model/blob/main/Cross-Level%20Requirements%20Tracing%20Based%20on%20Large%20Language%20Model/Data/Original_Data/CM1Dataset.csv | G11: None | H11: Requirements | I11: Pair | J11: management | K11: traceability | L11: aerospace | M11: 671 | N11: en | O11: Positive,Negative | P11: - | Q11: P049,P058,P116
A12: D011 | B12: CM1-Modis | C12: Cross-level requirements dataset for traceability tasks from the aerospace domain | D12: C. Ge, T. Wang, X. Yang and C. Treude, "Cross-Level Requirements Tracing Based on Large Language Models," in IEEE Transactions on Software Engineering, vol. 51, no. 7, pp. 2044-2066, July 2025, doi: 10.1109/TSE.2025.3572094. | E12: 2025 | F12: https://github.com/Gechuyan/Cross-Level-Requirements-Tracing-Based-on-Large-Language-Model/blob/main/Cross-Level%20Requirements%20Tracing%20Based%20on%20Large%20Language%20Model/Data/Original_Data/cross_project/CM1-Modis.csv | G12: None | H12: Requirements | I12: Pair | J12: management | K12: traceability | L12: aerospace | M12: 720 | N12: en | O12: Positive,Negative | P12: D010,D036 | Q12: P049
A13: D012 | B13: CoffeeMachine_conflicts | C13: Collection of requirement datasets from the CoffeeMachine project labelled with inconsistencies between requirement pairs. | D13: Alessandro Fantechi, Stefania Gnesi, Lucia Passaro, & Laura Semini. (2023). Supplementary material for: Inconsistency Detection in Natural Language Requirements using ChatGPT: a Preliminary Evaluation [Data set]. Zenodo. https://doi.org/10.5281/zenodo.8089810 | E13: 2023 | F13: https://zenodo.org/records/8089810 | G13: Creative Commons Attribution Share Alike 4.0 International | H13: Requirements | I13: Pair | J13: management | K13: traceability | L13: services | M13: 29 | N13: en | O13: Consistent,Inconsistent | P13: - | Q13: P047
... A63: D062 | B63: Yilongfei2024_2 | C63: Derived from a public dataset on Huggingface about NL-LTL | D63: Y. Xu, J. Feng and W. Miao, "Learning from Failures: Translation of Natural Language Requirements into Linear Temporal Logic with Large Language Models," 2024 IEEE 24th International Conference on Software Quality, Reliability and Security (QRS), Cambridge, United Kingdom, 2024, pp. 204-215, doi: 10.1109/QRS62785.2024.00029. | E63: 2024 | F63: https://github.com/AnonymousBreeze/LTL-Learner/blob/master/Dataset/Dataset_2.xlsx | G63: None | H63: Requirements | I63: Document | J63: specification | K63: modelling | L63: railway,automotive | M63: 241 | N63: en | O63: - | P63: - | Q63: P097

Sheet metadata
B1: Description | C1: Values
A2: Code | B2: Unique dataset identifier used in this review. | C2: Open: ^D\d{3}$
A3: Name | B3: Name Short name chosen by the authors or assigned in this review for clarity. | C3: Open: short string
A4: Description | B4: Description Concise summary of the dataset content and purpose. | C4: Open: free text
A5: Reference | B5: Reference Full citation to the dataset source or accompanying publication. | C5: Open: citation string (APA)
A6: Year | B6: Year Publication or release year of the dataset. | C6: Open: 4-digit integer YYYY
A7: URL | B7: URL Persistent link to the dataset or its landing page. | C7: Open: URL
A8: License | B8: License SPDX identifier or textual license label if no SPDX applies. | C8: Closed: SPDX code
A9: Artifact type | B9: Artifact type Type of textual artifact represented in the dataset. | C9: Closed: Bug, QA, Requirements, User reviews, Legal text, Post, Questions, User stories, Other
A10: Granularity | B10: Granularity Unit of annotation or analysis in the dataset. | C10: Closed: Document, Sentence, Pair, Token, Other
A11: RE stage | B11: RE stage RE stage targeted by the dataset or its primary usage. | C11: Closed: elicitation, analysis, specification, management, verification & validation, other
A12: Task | B12: Task Primary computational task supported by the dataset. | C12: Closed: classification, extraction, traceability, modelling, Q&A, other
A13: Domain | B13: Domain Application or organizational domain. | C13: Open: short string
... A18: Publications | B18: Publications List of publication IDs that use the dataset. Comma-separated. | C18: Open: comma-separated list of publication IDs

Sheet plots
A1: Source | B1: Domain | C1: Dataset_Count | O1: verification & validation
A2: GitHub | B2: github.com | C2: 23 | O2: analysis
A3: Zenodo | B3: zenodo.org | C3: 16 | O3: specification
A4: GitFront | B4: gitfront.io | C4: 6 | O4: verification & validation
A5: Hugging Face | B5: huggingface.co | C5: 5 | O5: verification & validation
A6: Mendeley | B6: data.mendeley.com | C6: 2 | O6: analysis
A7: IEEE Dataport | B7: ieee-dataport.org | C7: 1 | O7: specification
A8: Figshare | B8: figshare.com | C8: 1 | O8: management
A9: Anonymous Open Science | B9: anonymous.4open.science | C9: 1 | O9: management
A10: Elsevier (DOI) | B10: elsevier.com | C10: 1 | O10: management
A11: Project website | B11: dronology.info | C11: 1 | O11: management
A12: Springer Link | B12: static-content.springer.com | C12: 1 | O12: management
A13: IEEE Xplore | B13: ieeexplore.ieee.org | C13: 1 | O13: elicitation
... A16: Sites GOogle | B16: sites.google.com | C16: 1 | O16: analysis
O17: elicitation
A18: Source | B18: #datasets | O18: management
A19: GitHub | B19: 23 | O19: management
A20: Zenodo | B20: 16 | O20: management
A21: GitFront | B21: 6 | O21: management
A22: Hugging Face | B22: 5 | O22: verification & validation
A23: Mendeley Data | B23: 2 | O23: verification & validation
A24: Others | B24: 10 | O24: verification & validation
O25: specification
O26: management
O27: management
O28: management
O29: verification & validation
O30: verification & validation
O31: specification
O32: analysis
O33: management
O34: specification
O35: analysis
O36: management
... O46: management
A47: Year | B47: #datasets | C47: #papers | O47: management
A48: 2016 | B48: =COUNTIF(datasets!E$2:E1846,A48) -> 1 | O48: specification
A49: 2017 | B49: =COUNTIF(datasets!E$2:E1846,A49) -> 0 | O49: management
A50: 2018 | B50: =COUNTIF(datasets!E$2:E1846,A50) -> 3 | O50: analysis
A51: 2019 | B51: =COUNTIF(datasets!E$2:E1846,A51) -> 4 | O51: analysis
...
